Workbook

Sheet بيان كهربة 54 (2)
A1: وزارة الاسكان والمرافق والمجتمعات العمرانية | V1: بيان أعمال كهرباء مستخلص جارى رقم (33 )
A2: هيئة المجتمعات العمرانية الجديدة | V2: الاعمال من بدء العمل حتى31 / 8 / 2025
K3: مشروع انشاء 54 عمارة- المرحلة الخامسة الحي ( 15 ) - اسكان اجتماعي مدينة العبور الجديدة
B4: جهاز مدينة العبور الجديدة | X4: مقاولة شركة المهندس / احمد سعد حسن للمقاولات المتكاملة
T5: بأمر اسناد رقم ( 66) بتاريخ 15/9/2022
A6: رقم البند | B6: بيــــــــــــــــان أعمال الكهـــــرباء | C6: الوحده | D6: كمية العمارة الواحدة بالمقاسة | E6: الموقف التنفيذي | F6: عدد العمارات | G6: ارقام العمــــــــــــــــــــــــارات | BI6: الاجمالي | BJ6: اجمالي العمارات
G7: 300 | H7: 301 | I7: 302 | J7: 303 | K7: 304 | L7: 305 | M7: 306 | N7: 307 | O7: 308 | P7: 309 | Q7: 310 | R7: 311 | S7: 312 | T7: 313 | U7: 314 | V7: 315 | W7: 316 | X7: 317 | Y7: 318 | Z7: 319 | AA7: 320 | AB7: 321 | AC7: 322 | AD7: 323 | AE7: 324 | AF7: 325 | AG7: 326 | AH7: 327 | AI7: 328 | AJ7: 329 | AK7: 330 | AL7: 331 | AM7: 332 | AN7: 333 | AO7: 334 | AP7: 335 | AQ7: 336 | AR7: 337 | AS7: 338 | AT7: 339 | AU7: 340 | AV7: 341 | AW7: 342 | AX7: 343 | AY7: 344 | AZ7: 345 | BA7: 346 | BB7: 347 | BC7: 348 | BD7: 349 | BE7: 350 | BF7: 351 | BG7: 352 | BH7: 353
A8: 1 | B8: بالعدد توريد وتركيب كوفريه عمومي من الصاج - 6 قواعد فيوز (الفيوز =250 أمبير ) | C8: بالعدد | D8: 1 | E8: صاج | F8: =(SUM(G8:BH8))/D8 -> 54 | G8: 1 | H8: 1 | I8: 1 | J8: 1 | K8: 1 | L8: 1 | M8: 1 | N8: 1 | O8: 1 | P8: 1 | Q8: 1 | R8: 1 | S8: 1 | T8: 1 | U8: 1 | V8: 1 | W8: 1 | X8: 1 | Y8: 1 | Z8: 1 | AA8: 1 | AB8: 1 | AC8: 1 | AD8: 1 | AE8: 1 | AF8: 1 | AG8: 1 | AH8: 1 | AI8: 1 | AJ8: 1 | AK8: 1 | AL8: 1 | AM8: 1 | AN8: 1 | AO8: 1 | AP8: 1 | AQ8: 1 | AR8: 1 | AS8: 1 | AT8: 1 | AU8: 1 | AV8: 1 | AW8: 1 | AX8: 1 | AY8: 1 | AZ8: 1 | BA8: 1 | BB8: 1 | BC8: 1 | BD8: 1 | BE8: 1 | BF8: 1 | BG8: 1 | BH8: 1 | BI8: =SUM(G8:BH8) -> 54
A9: 2 | B9: بالعدد توريد وتركيب صندوق توزيع بالادوار من الصاج بأبعاد 40*40سم وعمق 15 سم | C9: بالعدد | D9: 12 | E9: صاج | F9: =BI9/D9 -> 54 | G9: 12 | H9: 12 | I9: 12 | J9: 12 | K9: 12 | L9: 12 | M9: 12 | N9: 12 | O9: 12 | P9: 12 | Q9: 12 | R9: 12 | S9: 12 | T9: 12 | U9: 12 | V9: 12 | W9: 12 | X9: 12 | Y9: 12 | Z9: 12 | AA9: 12 | AB9: 12 | AC9: 12 | AD9: 12 | AE9: 12 | AF9: 12 | AG9: 12 | AH9: 12 | AI9: 12 | AJ9: 12 | AK9: 12 | AL9: 12 | AM9: 12 | AN9: 12 | AO9: 12 | AP9: 12 | AQ9: 12 | AR9: 12 | AS9: 12 | AT9: 12 | AU9: 12 | AV9: 12 | AW9: 12 | AX9: 12 | AY9: 12 | AZ9: 12 | BA9: 12 | BB9: 12 | BC9: 12 | BD9: 12 | BE9: 12 | BF9: 12 | BG9: 12 | BH9: 12 | BI9: =SUM(G9:BH9) -> 648 | BJ9: =#REF!/D9 -> #REF!
A10: 3 | B10: بالعدد توريد وتركيب كوفريه من الصاج لمداخل الشقق السكنيه | C10: بالعدد | D10: 24 | E10: صاج | F10: =BI10/D10 -> 0 | BI10: =SUM(G10:BH10) -> 0 | BJ10: =#REF!/D10 -> #REF!
E11: تشطيب | F11: =BI11/D10 -> 54 | G11: 24 | H11: 24 | I11: 24 | J11: 24 | K11: 24 | L11: 24 | M11: 24 | N11: 24 | O11: 24 | P11: 24 | Q11: 24 | R11: 24 | S11: 24 | T11: 24 | U11: 24 | V11: 24 | W11: 24 | X11: 24 | Y11: 24 | Z11: 24 | AA11: 24 | AB11: 24 | AC11: 24 | AD11: 24 | AE11: 24 | AF11: 24 | AG11: 24 | AH11: 24 | AI11: 24 | AJ11: 24 | AK11: 24 | AL11: 24 | AM11: 24 | AN11: 24 | AO11: 24 | AP11: 24 | AQ11: 24 | AR11: 24 | AS11: 24 | AT11: 24 | AU11: 24 | AV11: 24 | AW11: 24 | AX11: 24 | AY11: 24 | AZ11: 24 | BA11: 24 | BB11: 24 | BC11: 24 | BD11: 24 | BE11: 24 | BF11: 24 | BG11: 24 | BH11: 24 | BI11: =SUM(G11:BH11) -> 1296
A12: 4 | B12: بالعدد توريد وتركيب لوحه فرعيه للشقق | C12: بالعدد | D12: 24 | E12: صاج | F12: =BI12/D12 -> 0 | BI12: =SUM(G12:BH12) -> 0
E13: تشطيب | F13: =BI13/D12 -> 54 | G13: 24 | H13: 24 | I13: 24 | J13: 24 | K13: 24 | L13: 24 | M13: 24 | N13: 24 | O13: 24 | P13: 24 | Q13: 24 | R13: 24 | S13: 24 | T13: 24 | U13: 24 | V13: 24 | W13: 24 | X13: 24 | Y13: 24 | Z13: 24 | AA13: 24 | AB13: 24 | AC13: 24 | AD13: 24 | AE13: 24 | AF13: 24 | AG13: 24 | AH13: 24 | AI13: 24 | AJ13: 24 | AK13: 24 | AL13: 24 | AM13: 24 | AN13: 24 | AO13: 24 | AP13: 24 | AQ13: 24 | AR13: 24 | AS13: 24 | AT13: 24 | AU13: 24 | AV13: 24 | AW13: 24 | AX13: 24 | AY13: 24 | AZ13: 24 | BA13: 24 | BB13: 24 | BC13: 24 | BD13: 24 | BE13: 24 | BF13: 24 | BG13: 24 | BH13: 24 | BI13: =SUM(G13:BH13) -> 1296
A14: 5 | B14: بالعدد توريد وتركيب لوحه فرعيه للخدمات لاناره المداخل والسلالم | C14: بالعدد | D14: 1 | E14: صاج | F14: =BI14/D14 -> 0 | BI14: =SUM(G14:BH14) -> 0
E15: تشطيب | F15: =BI15/D14 -> 54 | G15: 1 | H15: 1 | I15: 1 | J15: 1 | K15: 1 | L15: 1 | M15: 1 | N15: 1 | O15: 1 | P15: 1 | Q15: 1 | R15: 1 | S15: 1 | T15: 1 | U15: 1 | V15: 1 | W15: 1 | X15: 1 | Y15: 1 | Z15: 1 | AA15: 1 | AB15: 1 | AC15: 1 | AD15: 1 | AE15: 1 | AF15: 1 | AG15: 1 | AH15: 1 | AI15: 1 | AJ15: 1 | AK15: 1 | AL15: 1 | AM15: 1 | AN15: 1 | AO15: 1 | AP15: 1 | AQ15: 1 | AR15: 1 | AS15: 1 | AT15: 1 | AU15: 1 | AV15: 1 | AW15: 1 | AX15: 1 | AY15: 1 | AZ15: 1 | BA15: 1 | BB15: 1 | BC15: 1 | BD15: 1 | BE15: 1 | BF15: 1 | BG15: 1 | BH15: 1 | BI15: =SUM(G15:BH15) -> 54
A16: 6 | B16: بالعدد توريد وتركيب لوحه عداد الشقه | C16: بالعدد | D16: 24 | E16: صاج | F16: =BI16/D16 -> 54 | G16: 24 | H16: 24 | I16: 24 | J16: 24 | K16: 24 | L16: 24 | M16: 24 | N16: 24 | O16: 24 | P16: 24 | Q16: 24 | R16: 24 | S16: 24 | T16: 24 | U16: 24 | V16: 24 | W16: 24 | X16: 24 | Y16: 24 | Z16: 24 | AA16: 24 | AB16: 24 | AC16: 24 | AD16: 24 | AE16: 24 | AF16: 24 | AG16: 24 | AH16: 24 | AI16: 24 | AJ16: 24 | AK16: 24 | AL16: 24 | AM16: 24 | AN16: 24 | AO16: 24 | AP16: 24 | AQ16: 24 | AR16: 24 | AS16: 24 | AT16: 24 | AU16: 24 | AV16: 24 | AW16: 24 | AX16: 24 | AY16: 24 | AZ16: 24 | BA16: 24 | BB16: 24 | BC16: 24 | BD16: 24 | BE16: 24 | BF16: 24 | BG16: 24 | BH16: 24 | BI16: =SUM(G16:BH16) -> 1296
A17: 7 | B17: بالمقطوعيه توريد وتركيب عدد 2 ماسوره بلاستيك قطر 29 بوصه ومسارها من لوحه الخدمات بالعماره وحتي سطح العماره | C17: مقط | D17: 1 | E17: صاج | F17: =(SUM(G17:BH17))/D17 -> 54 | G17: 1 | H17: 1 | I17: 1 | J17: 1 | K17: 1 | L17: 1 | M17: 1 | N17: 1 | O17: 1 | P17: 1 | Q17: 1 | R17: 1 | S17: 1 | T17: 1 | U17: 1 | V17: 1 | W17: 1 | X17: 1 | Y17: 1 | Z17: 1 | AA17: 1 | AB17: 1 | AC17: 1 | AD17: 1 | AE17: 1 | AF17: 1 | AG17: 1 | AH17: 1 | AI17: 1 | AJ17: 1 | AK17: 1 | AL17: 1 | AM17: 1 | AN17: 1 | AO17: 1 | AP17: 1 | AQ17: 1 | AR17: 1 | AS17: 1 | AT17: 1 | AU17: 1 | AV17: 1 | AW17: 1 | AX17: 1 | AY17: 1 | AZ17: 1 | BA17: 1 | BB17: 1 | BC17: 1 | BD17: 1 | BE17: 1 | BF17: 1 | BG17: 1 | BH17: 1 | BI17: =SUM(G17:BH17) -> 54
A18: 8 | B18: بالمتر الطولي توريد وتركيب العامود الصاعد 4 (1*50) + 1(1*35) | C18: م.ط | D18: 70 | E18: دق وتركيب | F18: 54 | G18: 58 | H18: 58 | I18: 58 | J18: 58 | K18: 58 | L18: 58 | M18: 58 | N18: 58 | O18: 58 | P18: 58 | Q18: 58 | R18: 58 | S18: 58 | T18: 58 | U18: 58 | V18: 58 | W18: 58 | X18: 58 | Y18: 58 | Z18: 58 | AA18: 58 | AB18: 58 | AC18: 58 | AD18: 58 | AE18: 58 | AF18: 58 | AG18: 58 | AH18: 58 | AI18: 58 | AJ18: 58 | AK18: 58 | AL18: 58 | AM18: 58 | AN18: 58 | AO18: 58 | AP18: 58 | AQ18: 58 | AR18: 58 | AS18: 58 | AT18: 58 | AU18: 58 | AV18: 58 | AW18: 58 | AX18: 58 | AY18: 58 | AZ18: 58 | BA18: 58 | BB18: 58 | BC18: 58 | BD18: 58 | BE18: 58 | BF18: 58 | BG18: 58 | BH18: 58 | BI18: =SUM(G18:BH18) -> 3132
A19: 9 | B19: توريد وتركيب خط تغذية الشقة ولوحة الخدمات من موصلات نحاس قطاع 2( 1 × 16 ) + ( 1 × 16 ) مم | C19: م.ط | D19: 192 | E19: دق وتركيب | F19: =BI19/192 -> 0 | BI19: =SUM(G19:BH19) -> 0
F20: =BI20/192 -> 54 | G20: 192 | H20: 192 | I20: 192 | J20: 192 | K20: 192 | L20: 192 | M20: 192 | N20: 192 | O20: 192 | P20: 192 | Q20: 192 | R20: 192 | S20: 192 | T20: 192 | U20: 192 | V20: 192 | W20: 192 | X20: 192 | Y20: 192 | Z20: 192 | AA20: 192 | AB20: 192 | AC20: 192 | AD20: 192 | AE20: 192 | AF20: 192 | AG20: 192 | AH20: 192 | AI20: 192 | AJ20: 192 | AK20: 192 | AL20: 192 | AM20: 192 | AN20: 192 | AO20: 192 | AP20: 192 | AQ20: 192 | AR20: 192 | AS20: 192 | AT20: 192 | AU20: 192 | AV20: 192 | AW20: 192 | AX20: 192 | AY20: 192 | AZ20: 192 | BA20: 192 | BB20: 192 | BC20: 192 | BD20: 192 | BE20: 192 | BF20: 192 | BG20: 192 | BH20: 192 | BI20: =SUM(G20:BH20) -> 10368
A21: 10 | B21: جلوب حوض غسيل ايدي وباب الشقه | C21: عدد | D21: 48 | E21: اكسسوار | F21: =(SUM(G21:BH21))/D21 -> 54 | G21: 48 | H21: 48 | I21: 48 | J21: 48 | K21: 48 | L21: 48 | M21: 48 | N21: 48 | O21: 48 | P21: 48 | Q21: 48 | R21: 48 | S21: 48 | T21: 48 | U21: 48 | V21: 48 | W21: 48 | X21: 48 | Y21: 48 | Z21: 48 | AA21: 48 | AB21: 48 | AC21: 48 | AD21: 48 | AE21: 48 | AF21: 48 | AG21: 48 | AH21: 48 | AI21: 48 | AJ21: 48 | AK21: 48 | AL21: 48 | AM21: 48 | AN21: 48 | AO21: 48 | AP21: 48 | AQ21: 48 | AR21: 48 | AS21: 48 | AT21: 48 | AU21: 48 | AV21: 48 | AW21: 48 | AX21: 48 | AY21: 48 | AZ21: 48 | BA21: 48 | BB21: 48 | BC21: 48 | BD21: 48 | BE21: 48 | BF21: 48 | BG21: 48 | BH21: 48 | BI21: =SUM(G21:BH21) -> 2592
A22: 11 | B22: توريد وتركيب مخرج إنارة بالسقف أو الحائط | C22: بالعدد | D22: 192 | E22: دق وتركيب | F22: =(SUM(G22:BH22))/D22 -> 0 | BI22: =SUM(G22:BH22) -> 0
E23: سلك | F23: =(SUM(G23:BH23))/D22 -> 54 | G23: 192 | H23: 192 | I23: 192 | J23: 192 | K23: 192 | L23: 192 | M23: 192 | N23: 192 | O23: 192 | P23: 192 | Q23: 192 | R23: 192 | S23: 192 | T23: 192 | U23: 192 | V23: 192 | W23: 192 | X23: 192 | Y23: 192 | Z23: 192 | AA23: 192 | AB23: 192 | AC23: 192 | AD23: 192 | AE23: 192 | AF23: 192 | AG23: 192 | AH23: 192 | AI23: 192 | AJ23: 192 | AK23: 192 | AL23: 192 | AM23: 192 | AN23: 192 | AO23: 192 | AP23: 192 | AQ23: 192 | AR23: 192 | AS23: 192 | AT23: 192 | AU23: 192 | AV23: 192 | AW23: 192 | AX23: 192 | AY23: 192 | AZ23: 192 | BA23: 192 | BB23: 192 | BC23: 192 | BD23: 192 | BE23: 192 | BF23: 192 | BG23: 192 | BH23: 192 | BI23: =SUM(G23:BH23) -> 10368 | BK23: =#REF!-BI24 -> #REF! | BL23: =BI24 -> 0
A24: 12 | B24: توريد وتركيب مخرج نجفه | C24: بالعدد | D24: 120 | E24: دق وتركيب | F24: =(SUM(G24:BH24))/D24 -> 0 | BI24: =SUM(G24:BH24) -> 0
E25: سلك | F25: =(SUM(G25:BH25))/D24 -> 54 | G25: 120 | H25: 120 | I25: 120 | J25: 120 | K25: 120 | L25: 120 | M25: 120 | N25: 120 | O25: 120 | P25: 120 | Q25: 120 | R25: 120 | S25: 120 | T25: 120 | U25: 120 | V25: 120 | W25: 120 | X25: 120 | Y25: 120 | Z25: 120 | AA25: 120 | AB25: 120 | AC25: 120 | AD25: 120 | AE25: 120 | AF25: 120 | AG25: 120 | AH25: 120 | AI25: 120 | AJ25: 120 | AK25: 120 | AL25: 120 | AM25: 120 | AN25: 120 | AO25: 120 | AP25: 120 | AQ25: 120 | AR25: 120 | AS25: 120 | AT25: 120 | AU25: 120 | AV25: 120 | AW25: 120 | AX25: 120 | AY25: 120 | AZ25: 120 | BA25: 120 | BB25: 120 | BC25: 120 | BD25: 120 | BE25: 120 | BF25: 120 | BG25: 120 | BH25: 120 | BI25: =SUM(G25:BH25) -> 6480 | BK25: =#REF!-BI26 -> #REF! | BL25: =SUM(G26:BH26) -> 0
A26: 13 | B26: توريد وتركيب مخرج اناره للمدخل او السلم | C26: بالعدد | D26: 17 | E26: دق وتركيب | F26: =(SUM(G26:BH26))/D26 -> 0 | BI26: =SUM(G26:BH26) -> 0 | BL26: =BI28 -> 0
E27: سلك | F27: =(SUM(G27:BH27))/D26 -> 54 | G27: 17 | H27: 17 | I27: 17 | J27: 17 | K27: 17 | L27: 17 | M27: 17 | N27: 17 | O27: 17 | P27: 17 | Q27: 17 | R27: 17 | S27: 17 | T27: 17 | U27: 17 | V27: 17 | W27: 17 | X27: 17 | Y27: 17 | Z27: 17 | AA27: 17 | AB27: 17 | AC27: 17 | AD27: 17 | AE27: 17 | AF27: 17 | AG27: 17 | AH27: 17 | AI27: 17 | AJ27: 17 | AK27: 17 | AL27: 17 | AM27: 17 | AN27: 17 | AO27: 17 | AP27: 17 | AQ27: 17 | AR27: 17 | AS27: 17 | AT27: 17 | AU27: 17 | AV27: 17 | AW27: 17 | AX27: 17 | AY27: 17 | AZ27: 17 | BA27: 17 | BB27: 17 | BC27: 17 | BD27: 17 | BE27: 17 | BF27: 17 | BG27: 17 | BH27: 17 | BI27: =SUM(G27:BH27) -> 918 | BK27: =#REF!-BI28 -> #REF!
A28: 15 | B28: توريد وتركيب مخرج إنارة لمدخل العمارة ( أسقف أرضي ) | C28: بالعدد | D28: 2 | E28: دق وتركيب | F28: =(SUM(G28:BH28))/D28 -> 0 | BI28: =SUM(G28:BH28) -> 0
E29: سلك | F29: =(SUM(G29:BH29))/D28 -> 54 | G29: 2 | H29: 2 | I29: 2 | J29: 2 | K29: 2 | L29: 2 | M29: 2 | N29: 2 | O29: 2 | P29: 2 | Q29: 2 | R29: 2 | S29: 2 | T29: 2 | U29: 2 | V29: 2 | W29: 2 | X29: 2 | Y29: 2 | Z29: 2 | AA29: 2 | AB29: 2 | AC29: 2 | AD29: 2 | AE29: 2 | AF29: 2 | AG29: 2 | AH29: 2 | AI29: 2 | AJ29: 2 | AK29: 2 | AL29: 2 | AM29: 2 | AN29: 2 | AO29: 2 | AP29: 2 | AQ29: 2 | AR29: 2 | AS29: 2 | AT29: 2 | AU29: 2 | AV29: 2 | AW29: 2 | AX29: 2 | AY29: 2 | AZ29: 2 | BA29: 2 | BB29: 2 | BC29: 2 | BD29: 2 | BE29: 2 | BF29: 2 | BG29: 2 | BH29: 2 | BI29: =SUM(G29:BH29) -> 108 | BK29: =#REF!-BI30 -> #REF! | BL29: =BI30 -> 0
A30: 16 | B30: توريد وتركيب مخرج جرس | C30: بالعدد | D30: 24 | E30: دق وتركيب | F30: =(SUM(G30:BH30))/D30 -> 0 | BI30: =SUM(G30:BH30) -> 0
E31: سلك | F31: =(SUM(G31:BH31))/D30 -> 54 | G31: 24 | H31: 24 | I31: 24 | J31: 24 | K31: 24 | L31: 24 | M31: 24 | N31: 24 | O31: 24 | P31: 24 | Q31: 24 | R31: 24 | S31: 24 | T31: 24 | U31: 24 | V31: 24 | W31: 24 | X31: 24 | Y31: 24 | Z31: 24 | AA31: 24 | AB31: 24 | AC31: 24 | AD31: 24 | AE31: 24 | AF31: 24 | AG31: 24 | AH31: 24 | AI31: 24 | AJ31: 24 | AK31: 24 | AL31: 24 | AM31: 24 | AN31: 24 | AO31: 24 | AP31: 24 | AQ31: 24 | AR31: 24 | AS31: 24 | AT31: 24 | AU31: 24 | AV31: 24 | AW31: 24 | AX31: 24 | AY31: 24 | AZ31: 24 | BA31: 24 | BB31: 24 | BC31: 24 | BD31: 24 | BE31: 24 | BF31: 24 | BG31: 24 | BH31: 24 | BI31: =SUM(G31:BH31) -> 1296 | BK31: =#REF!-BI32 -> #REF! | BL31: =BI32 -> 0
A32: 17 | B32: توريد وتركيب مخرج بريزة عادية | C32: بالعدد | D32: 384 | E32: دق وتركيب | F32: =(SUM(G32:BH32))/480 -> 0 | BI32: =SUM(G32:BH32) -> 0
E33: سلك | F33: =SUM(G33:BH33)/480 -> 54 | G33: 480 | H33: 480 | I33: 480 | J33: 480 | K33: 480 | L33: 480 | M33: 480 | N33: 480 | O33: 480 | P33: 480 | Q33: 480 | R33: 480 | S33: 480 | T33: 480 | U33: 480 | V33: 480 | W33: 480 | X33: 480 | Y33: 480 | Z33: 480 | AA33: 480 | AB33: 480 | AC33: 480 | AD33: 480 | AE33: 480 | AF33: 480 | AG33: 480 | AH33: 480 | AI33: 480 | AJ33: 480 | AK33: 480 | AL33: 480 | AM33: 480 | AN33: 480 | AO33: 480 | AP33: 480 | AQ33: 480 | AR33: 480 | AS33: 480 | AT33: 480 | AU33: 480 | AV33: 480 | AW33: 480 | AX33: 480 | AY33: 480 | AZ33: 480 | BA33: 480 | BB33: 480 | BC33: 480 | BD33: 480 | BE33: 480 | BF33: 480 | BG33: 480 | BH33: 480 | BI33: =SUM(G33:BH33) -> 25920 | BK33: =#REF!-BI34 -> #REF! | BL33: =SUM(G34:BH34) -> 0
A34: 18 | B34: توريد وتركيب مخرج بريزة قوى | C34: بالعدد | D34: 48 | E34: دق وتركيب | F34: =(SUM(G34:BH34))/D34 -> 0 | BI34: =SUM(G34:BH34) -> 0
E35: سلك | F35: =(SUM(G35:BH35))/D34 -> 54 | G35: 48 | H35: 48 | I35: 48 | J35: 48 | K35: 48 | L35: 48 | M35: 48 | N35: 48 | O35: 48 | P35: 48 | Q35: 48 | R35: 48 | S35: 48 | T35: 48 | U35: 48 | V35: 48 | W35: 48 | X35: 48 | Y35: 48 | Z35: 48 | AA35: 48 | AB35: 48 | AC35: 48 | AD35: 48 | AE35: 48 | AF35: 48 | AG35: 48 | AH35: 48 | AI35: 48 | AJ35: 48 | AK35: 48 | AL35: 48 | AM35: 48 | AN35: 48 | AO35: 48 | AP35: 48 | AQ35: 48 | AR35: 48 | AS35: 48 | AT35: 48 | AU35: 48 | AV35: 48 | AW35: 48 | AX35: 48 | AY35: 48 | AZ35: 48 | BA35: 48 | BB35: 48 | BC35: 48 | BD35: 48 | BE35: 48 | BF35: 48 | BG35: 48 | BH35: 48 | BI35: =SUM(G35:BH35) -> 2592 | BK35: =#REF!-BI36 -> #REF! | BL35: =SUM(G36:BH36) -> 0
A36: 19 | B36: توريد وتركيب مخرج تكييف ) | C36: بالعدد | D36: 24 | E36: خراطيم | F36: =(SUM(G36:BH36))/D36 -> 0 | BI36: =SUM(G36:BH36) -> 0
E37: دق وتركيب + خراطيم | F37: =(SUM(G37:BH37))/D36 -> 54 | G37: 24 | H37: 24 | I37: 24 | J37: 24 | K37: 24 | L37: 24 | M37: 24 | N37: 24 | O37: 24 | P37: 24 | Q37: 24 | R37: 24 | S37: 24 | T37: 24 | U37: 24 | V37: 24 | W37: 24 | X37: 24 | Y37: 24 | Z37: 24 | AA37: 24 | AB37: 24 | AC37: 24 | AD37: 24 | AE37: 24 | AF37: 24 | AG37: 24 | AH37: 24 | AI37: 24 | AJ37: 24 | AK37: 24 | AL37: 24 | AM37: 24 | AN37: 24 | AO37: 24 | AP37: 24 | AQ37: 24 | AR37: 24 | AS37: 24 | AT37: 24 | AU37: 24 | AV37: 24 | AW37: 24 | AX37: 24 | AY37: 24 | AZ37: 24 | BA37: 24 | BB37: 24 | BC37: 24 | BD37: 24 | BE37: 24 | BF37: 24 | BG37: 24 | BH37: 24 | BI37: =SUM(G37:BH37) -> 1296
A38: 20 | B38: بالعدد توريد وتركيب مفتاح اناره داخل الحائط (سكه واحده) | C38: بالعدد | D38: 72 | E38: تشطيب | F38: =(SUM(G38:BH38))/D38 -> 54 | G38: 72 | H38: 72 | I38: 72 | J38: 72 | K38: 72 | L38: 72 | M38: 72 | N38: 72 | O38: 72 | P38: 72 | Q38: 72 | R38: 72 | S38: 72 | T38: 72 | U38: 72 | V38: 72 | W38: 72 | X38: 72 | Y38: 72 | Z38: 72 | AA38: 72 | AB38: 72 | AC38: 72 | AD38: 72 | AE38: 72 | AF38: 72 | AG38: 72 | AH38: 72 | AI38: 72 | AJ38: 72 | AK38: 72 | AL38: 72 | AM38: 72 | AN38: 72 | AO38: 72 | AP38: 72 | AQ38: 72 | AR38: 72 | AS38: 72 | AT38: 72 | AU38: 72 | AV38: 72 | AW38: 72 | AX38: 72 | AY38: 72 | AZ38: 72 | BA38: 72 | BB38: 72 | BC38: 72 | BD38: 72 | BE38: 72 | BF38: 72 | BG38: 72 | BH38: 72 | BI38: =SUM(G38:BH38) -> 3888
A39: 21 | B39: بالعدد توريد وتركيب مفتاح اناره داخل الحائط ( سكتين ) | C39: بالعدد | D39: 120 | E39: تشطيب | F39: =(SUM(G39:BH39))/D39 -> 54 | G39: 120 | H39: 120 | I39: 120 | J39: 120 | K39: 120 | L39: 120 | M39: 120 | N39: 120 | O39: 120 | P39: 120 | Q39: 120 | R39: 120 | S39: 120 | T39: 120 | U39: 120 | V39: 120 | W39: 120 | X39: 120 | Y39: 120 | Z39: 120 | AA39: 120 | AB39: 120 | AC39: 120 | AD39: 120 | AE39: 120 | AF39: 120 | AG39: 120 | AH39: 120 | AI39: 120 | AJ39: 120 | AK39: 120 | AL39: 120 | AM39: 120 | AN39: 120 | AO39: 120 | AP39: 120 | AQ39: 120 | AR39: 120 | AS39: 120 | AT39: 120 | AU39: 120 | AV39: 120 | AW39: 120 | AX39: 120 | AY39: 120 | AZ39: 120 | BA39: 120 | BB39: 120 | BC39: 120 | BD39: 120 | BE39: 120 | BF39: 120 | BG39: 120 | BH39: 120 | BI39: =SUM(G39:BH39) -> 6480
A40: 22 | B40: بالعدد توريد وتركيب مفتاح اناره داخل الحائط ( ثلاثه سكه) | C40: بالعدد | D40: 24 | E40: تشطيب | F40: =(SUM(G40:BH40))/D40 -> 54 | G40: 24 | H40: 24 | I40: 24 | J40: 24 | K40: 24 | L40: 24 | M40: 24 | N40: 24 | O40: 24 | P40: 24 | Q40: 24 | R40: 24 | S40: 24 | T40: 24 | U40: 24 | V40: 24 | W40: 24 | X40: 24 | Y40: 24 | Z40: 24 | AA40: 24 | AB40: 24 | AC40: 24 | AD40: 24 | AE40: 24 | AF40: 24 | AG40: 24 | AH40: 24 | AI40: 24 | AJ40: 24 | AK40: 24 | AL40: 24 | AM40: 24 | AN40: 24 | AO40: 24 | AP40: 24 | AQ40: 24 | AR40: 24 | AS40: 24 | AT40: 24 | AU40: 24 | AV40: 24 | AW40: 24 | AX40: 24 | AY40: 24 | AZ40: 24 | BA40: 24 | BB40: 24 | BC40: 24 | BD40: 24 | BE40: 24 | BF40: 24 | BG40: 24 | BH40: 24 | BI40: =SUM(G40:BH40) -> 1296
...

Sheet كهرباء 54
A1: وزارة الاسكان والمرافق والمجتمعات العمرانية | D1: مستخلص كهرباء جارى رقم (34 ) | L1: الاعمال المنفذه من بدء العمل الى 31-10-2025 | R1: عدد العمارات
D2: تنفيذ عدد 54 عمارة ضمن المرحلة الخامسة بالحى الــ 15 بالمدينة | R2: 32
A3: هيئة المجتمعات العمرانية الجديدة | D3: مقاولة / شركة المهندس / احمد سعد حسن عبد الجواد للمقاولات المتكاملة
A4: جهاز مدينة العبور الجديدة | D4: استشارى المشروع / مركز بحوث واستشارات التنمية - كلية الهندسة -جامعة الفيوم | L4: تاريخ بدء الاعمال 21 / 9 / 2022 تاريخ النهو المقرر 21 /3 / 2024 تاريخ النهو المعدل 2025/9/30
D5: بموجب أمر إسناد رقم ( 66 ) بتاريخ 15 / 9 / 2022
A6: رقم بند | B6: بنود الأعمال | D6: وحدة | E6: كمية المقايسة | F6: الكمية التعاقدية | G6: الفئة | I6: كمية الأعمال | L6: قيمة الأعمال | M6: نسبة الصرف | N6: قيمة الخصم بالجنية | O6: صافى القيمة | P6: ملاحظات
I7: السابق | J7: الجارى | K7: الجملة | L7: بالجنية | O7: بالجنية
A8: 1 | B8: بالعدد توريد وتركيب كوفريه عمومي من الصاج - 6 قواعد فيوز (الفيوز =250 أمبير ) | D8: عدد | E8: 1 | F8: =E8*54 -> 54 | G8: 8650 | I8: 54 | J8: =K8-I8 -> 0 | K8: 54 | L8: =G8*K8 -> 467100 | M8: 0.5 | N8: =L8*(1-M8) -> 233550 | O8: =L8-N8 -> 233550 | R8: =K8/E8 -> 54
A9: 2 | B9: بالعدد توريد وتركيب صندوق توزيع بالادوار من الصاج بأبعاد 40*40سم وعمق 15 سم | D9: عدد | E9: 12 | F9: =E9*54 -> 648 | G9: 320 | I9: 648 | J9: =K9-I9 -> 0 | K9: 648 | L9: =G9*K9 -> 207360 | M9: 0.8 | N9: =L9*(1-M9) -> 41472 | O9: =L9-N9 -> 165888 | R9: =K9/E9 -> 54
A10: 3 | B10: بالعدد توريد وتركيب كوفريه من الصاج لمداخل الشقق السكنيه | C10: صاج | D10: عدد | E10: 24 | F10: =E10*54 -> 1296 | G10: 350 | I10: 0 | J10: =K10-I10 -> 0 | K10: =F10-K11 -> 0 | L10: =G10*K10 -> 0 | M10: 0.25 | N10: =L10*(1-M10) -> 0 | O10: =L10-N10 -> 0 | R10: =K10/E10 -> 0
C11: تشطيب | I11: 1296 | J11: =K11-I11 -> 0 | K11: =54*24 -> 1296 | L11: =K11*G10 -> 453600 | M11: 0.95 | N11: =L11*(1-M11) -> 22680 | O11: =L11-N11 -> 430920
A12: 4 | B12: بالعدد توريد وتركيب لوحه فرعيه للشقق | C12: صاج | D12: عدد | E12: 24 | F12: =E12*54 -> 1296 | G12: 725 | I12: 0 | J12: =K12-I12 -> 0 | K12: =F12-K13 -> 0 | L12: =G12*K12 -> 0 | M12: 0.25 | N12: =L12*(1-M12) -> 0 | O12: =L12-N12 -> 0 | R12: =K12/E12 -> 0
C13: تشطيب | I13: 1296 | J13: =K13-I13 -> 0 | K13: =54*E12 -> 1296 | L13: =K13*G12 -> 939600 | M13: 0.95 | N13: =L13*(1-M13) -> 46980 | O13: =L13-N13 -> 892620
A14: 5 | B14: بالعدد توريد وتركيب لوحه فرعيه للخدمات لاناره المداخل والسلالم | C14: صاج | D14: عدد | E14: 1 | F14: =E14*54 -> 54 | G14: 535 | I14: 0 | J14: =K14-I14 -> 0 | K14: =F14-K15 -> 0 | L14: =K14*G14 -> 0 | M14: 0.25 | N14: =L14*(1-M14) -> 0 | O14: =L14-N14 -> 0 | R14: =K14/E14 -> 0
C15: تشطيب | I15: 54 | J15: =K15-I15 -> 0 | K15: 54 | L15: =K15*G14 -> 28890 | M15: 0.95 | N15: =L15*(1-M15) -> 1444.5 | O15: =L15-N15 -> 27445.5
A16: 6 | B16: بالعدد توريد وتركيب لوحه عداد الشقه ( صاج) | D16: عدد | E16: 24 | F16: =E16*54 -> 1296 | G16: 310 | I16: 1296 | J16: =K16-I16 -> 0 | K16: 1296 | L16: =G16*K16 -> 401760 | M16: 0.95 | N16: =L16*(1-M16) -> 20088 | O16: =L16-N16 -> 381672 | R16: =K16/E16 -> 54
A17: 7 | B17: بالمقطوعيه توريد وتركيب عدد 2 ماسوره بلاستيك قطر 29 بوصه | D17: مقط | E17: 1 | F17: =E17*54 -> 54 | G17: 800 | I17: 54 | J17: =K17-I17 -> 0 | K17: 54 | L17: =G17*K17 -> 43200 | M17: 0.95 | N17: =L17*(1-M17) -> 2160 | O17: =L17-N17 -> 41040 | R17: =K17/E17 -> 54
A18: 8 | B18: بالمتر الطولي توريد وتركيب العامود الصاعد 4 (1*50) + 1(1*35) | D18: م.ط | E18: 70 | F18: =E18*54 -> 3780 | G18: 930 | I18: 3132 | J18: =K18-I18 -> 0 | K18: 3132 | L18: =G18*K18 -> 2912760 | M18: 0.25 | N18: =L18*(1-M18) -> 2184570 | O18: =L18-N18 -> 728190 | R18: =K18/E18 -> 44.742857
A19: 9 | B19: توريد وتركيب خط تغذية الشقة من موصلات نحاس قطاع 2( 1 × 16 ) + ( 1 × 16 ) مم | D19: م.ط | E19: 192 | F19: =E19*54 -> 10368 | G19: 165 | I19: 0 | J19: =K19-I19 -> 0 | K19: =F19-K20 -> 0 | L19: =G19*K19 -> 0 | M19: 0.25 | N19: =L19*(1-M19) -> 0 | O19: =L19-N19 -> 0 | R19: =K19/E19 -> 0
I20: 10368 | J20: =K20-I20 -> 0 | K20: =54*192 -> 10368 | L20: =K20*G19 -> 1710720 | M20: 0.95 | N20: =L20*(1-M20) -> 85536 | O20: =L20-N20 -> 1625184
A21: 10 | B21: جلوب كروي لزوم حوض غسيل الايدي وباب الشقة | D21: عدد | E21: 48 | F21: =E21*54 -> 2592 | G21: 85 | I21: 2592 | J21: =K21-I21 -> 0 | K21: =54*E21 -> 2592 | L21: =G21*K21 -> 220320 | M21: 0.97 | N21: =L21*(1-M21) -> 6609.6 | O21: =L21-N21 -> 213710.4
A22: 11 | B22: توريد وتركيب مخرج إنارة بالسقف أو الحائط | C22: اسقف + دق وتركيب | D22: عدد | E22: 192 | F22: =E22*54 -> 10368 | G22: 300 | I22: 0 | J22: =K22-I22 -> 0 | K22: =F22-K23 -> 0 | L22: =K22*G22 -> 0 | M22: 0.25 | N22: =L22*(1-M22) -> 0 | O22: =L22-N22 -> 0 | Q22: =SUM(K22:K22) -> 0 | R22: =K22/E22 -> 0 | S22: =M22*K22 -> 0 | T22: =(O22-554396)/G22 -> -1847.9867
C23: سحب سلك | I23: 10368 | J23: =K23-I23 -> 0 | K23: =54*E22 -> 10368 | L23: =K23*G22 -> 3110400 | M23: 0.95 | N23: =L23*(1-M23) -> 155520 | O23: =L23-N23 -> 2954880 | Q23: =SUM(K22:K23) -> 10368 | R23: =K23/E23 -> #DIV/0!
A24: 12 | B24: توريد وتركيب مخرج نجفة | C24: اسقف + دق وتركيب | D24: عدد | E24: 120 | F24: =E24*54 -> 6480 | G24: 485 | I24: 0 | J24: =K24-I24 -> 0 | K24: =F24-K25 -> 0 | L24: =K24*G24 -> 0 | M24: 0.25 | N24: =L24*(1-M24) -> 0 | O24: =L24-N24 -> 0 | Q24: =SUM(K23:K24) -> 10368 | R24: =K24/E24 -> 0 | S24: =M24*K24 -> 0 | T24: =(O24-560171)/G24 -> -1154.9918
C25: سحب سلك | I25: 6480 | J25: =K25-I25 -> 0 | K25: =54*E24 -> 6480 | L25: =K25*G24 -> 3142800 | M25: 0.95 | N25: =L25*(1-M25) -> 157140 | O25: =L25-N25 -> 2985660 | Q25: =SUM(K24:K25) -> 6480 | R25: =K25/E25 -> #DIV/0!
A26: 13 | B26: توريد وتركيب مخرج إنارة بالمدخل والسلم | C26: اسقف + دق وتركيب | D26: عدد | E26: 17 | F26: =E26*54 -> 918 | G26: 250 | I26: 0 | J26: =K26-I26 -> 0 | K26: =F26-K27 -> 0 | L26: =K26*G26 -> 0 | M26: 0.25 | N26: =L26*(1-M26) -> 0 | O26: =L26-N26 -> 0 | Q26: =SUM(K25:K26) -> 6480 | R26: =K26/E26 -> 0 | S26: =M26*K26 -> 0 | T26: =(O26-40881)/G26 -> -163.524
C27: سحب سلك | I27: 918 | J27: =K27-I27 -> 0 | K27: =54*E26 -> 918 | L27: =K27*G26 -> 229500 | M27: 0.95 | N27: =L27*(1-M27) -> 11475 | O27: =L27-N27 -> 218025 | Q27: =SUM(K26:K27) -> 918 | R27: =K27/E27 -> #DIV/0!
A28: 15 | B28: توريد وتركيب مخرج إنارة مدخل العمارة | C28: اسقف + دق وتركيب | D28: عدد | E28: 2 | F28: =E28*54 -> 108 | G28: 400 | I28: 0 | J28: =K28-I28 -> 0 | K28: =F28-K29 -> 0 | L28: =K28*G28 -> 0 | M28: 0.25 | N28: =L28*(1-M28) -> 0 | O28: =L28-N28 -> 0 | Q28: =SUM(K27:K28) -> 918 | R28: =K28/E28 -> 0 | S28: =M28*K28 -> 0 | T28: =(O28-7781)/G28 -> -19.4525
C29: سحب سلك | I29: 108 | J29: =K29-I29 -> 0 | K29: =54*E28 -> 108 | L29: =K29*G28 -> 43200 | M29: 0.95 | N29: =L29*(1-M29) -> 2160 | O29: =L29-N29 -> 41040 | Q29: =SUM(K28:K29) -> 108 | R29: =K29/E29 -> #DIV/0!
A30: 16 | B30: توريد وتركيب مخرج إنارة مخرج جرس | C30: اسقف + دق وتركيب | D30: عدد | E30: 24 | F30: =E30*54 -> 1296 | G30: 165 | I30: 0 | J30: =K30-I30 -> 0 | K30: =F30-K31 -> 0 | L30: =K30*G30 -> 0 | M30: 0.25 | N30: =L30*(1-M30) -> 0 | O30: =L30-N30 -> 0 | Q30: =SUM(K29:K30) -> 108 | R30: =K30/E30 -> 0 | S30: =M30*K30 -> 0 | T30: =(O30-38115)/G30 -> -231
C31: سحب سلك | I31: 1296 | J31: =K31-I31 -> 0 | K31: =54*E30 -> 1296 | L31: =K31*G30 -> 213840 | M31: 0.95 | N31: =L31*(1-M31) -> 10692 | O31: =L31-N31 -> 203148 | Q31: =SUM(K30:K31) -> 1296 | R31: =K31/E31 -> #DIV/0!
A32: 17 | B32: توريد وتركيب مخرج بريزة عادية | C32: اسقف + دق وتركيب | D32: عدد | E32: 384 | F32: =E32*54 -> 20736 | G32: 230 | I32: 0 | J32: =K32-I32 -> 0 | K32: =25920-K33 -> 0 | L32: =K32*G32 -> 0 | M32: 0.25 | N32: =L32*(1-M32) -> 0 | O32: =L32-N32 -> 0 | Q32: =SUM(K31:K32) -> 1296 | R32: =K32/E32 -> 0 | S32: =M32*K32 -> 0 | T32: =(O32-850073)/G32 -> -3695.9696
C33: سحب سلك | I33: 25920 | J33: =K33-I33 -> 0 | K33: =54*480 -> 25920 | L33: =K33*G32 -> 5961600 | M33: 0.95 | N33: =L33*(1-M33) -> 298080 | O33: =L33-N33 -> 5663520 | Q33: =SUM(K32:K33) -> 25920 | R33: =K33/E33 -> #DIV/0!
A34: 18 | B34: توريد وتركيب مخرج بريزة قوى | C34: اسقف + دق وتركيب | D34: عدد | E34: 48 | F34: =E34*54 -> 2592 | G34: 415 | I34: 0 | J34: =K34-I34 -> 0 | K34: =2592-K35 -> 0 | L34: =K34*G34 -> 0 | M34: 0.25 | N34: =L34*(1-M34) -> 0 | O34: =L34-N34 -> 0 | R34: =K34/E34 -> 0 | S34: =M34*K34 -> 0 | T34: =(O34-191729)/G34 -> -461.99759
C35: سحب سلك | I35: 2592 | J35: =K35-I35 -> 0 | K35: =54*E34 -> 2592 | L35: =K35*G34 -> 1075680 | M35: 0.95 | N35: =L35*(1-M35) -> 53784 | O35: =L35-N35 -> 1021896 | R35: =K35/E35 -> #DIV/0!
A36: 19 | B36: توريد وتركيب مخرج تكييف | C36: اسقف + دق وتركيب | D36: عدد | E36: 24 | F36: =E36*54 -> 1296 | G36: 795 | I36: 0 | J36: =K36-I36 -> 0 | K36: =1296-K37 -> 0 | L36: =K36*G36 -> 0 | M36: 0.25 | N36: =L36*(1-M36) -> 0 | O36: =L36-N36 -> 0 | R36: =K36/E36 -> 0 | S36: =M36*K36 -> 0 | T36: =(O36-183644)/G36 -> -230.99874
C37: سحب سلك | I37: 1296 | J37: =K37-I37 -> 0 | K37: =54*E36 -> 1296 | L37: =K37*G36 -> 1030320 | M37: 0.95 | N37: =L37*(1-M37) -> 51516 | O37: =L37-N37 -> 978804 | R37: =K37/E37 -> #DIV/0!
A38: الاجمــــــــالي | L38: =SUM(L8:L37) -> 22192650 | N38: =SUM(N8:N37) -> 3385457.1 | O38: =SUM(O8:O37) -> 18807193
A39: ملاحظات :- المراجعه الماليه وخصم النسب المقرره طبقا للتعاقد مسئولية الاداره الماليه للجهاز
B40: يتم رفع جميع التعليات السابقة | D40: * الكميات المدرجة والمنفذة واعمال الحصر طبقا للمواصفات واصول الصناعة مسئولية الاستشارى المشرف على المشروع دون ادنى مسئولية على الجهاز | Q40: =SUM(K22:K23) -> 10368
...

Sheet اجمــــــــاليات 
A1: بيان مستخلص جــــــــاري رقـــــــــم (34 )
A2: البيان | B2: السابق | C2: الحالي | D2: الصـــــــافي
A3: اعتيادي | B3: 4.097945e+08 | C3: =مستخلص!M220*0.97 -> 4.1201186e+08 | D3: =C3-B3 -> 2217364.7
A4: كهرباء | B4: 21376080 | C4: =0.97*'كهرباء 54'!O84-300000*1 -> 21824275 | D4: =C4-B4 -> 448194.71 | E4: =0.1*447824000 -> 44782400
A5: تشوينات بعد خصم 25% | B5: 612846 | C5: =تشوينات!GA30 -> 612846 | D5: =C5-B5 -> 0 | E5: =408983660.61+775833.89 -> 4.0975949e+08
A6: الاجمـــــــــــــــــــالي | B6: =SUM(B3:B5) -> 4.3178342e+08 | C6: =SUM(C3:C5) -> 4.3444898e+08 | D6: =SUM(D3:D5) -> 2665559.4
A7: الصافي بدون تشوينات | D7: =D3+D4 -> 2665559.4 | E7: نننننننننننننننننننننننن
A8: الصافي بعد خصم الضريبة 5% | D8: =D7/1.05 -> 2538628
A9: الصافي بعد خصم الضريبه + التشوينات | D9: =D8+D5 -> 2538628
A10: الصافي المستحق بعد تعلية 3 % | D10: =D3+D4+D5 -> 2665559.4
A11: الاستقطاعات | B11: النسبة | C11: قيمة الاستقطاعات
A12: ضمان الاعمال | B12: 0.05 | C12: =B12*D7 -> 133277.97
A13: تامين الاشغالات | B13: 0.0027 | C13: =B13*D9 -> 6854.2956
A14: الدمغة النسبية | B14: 0.006 | C14: =B14*D9 -> 15231.768
A15: الدمغة الإضافية | B15: 0.018 | C15: =B15*D9 -> 45695.304
A16: دمغة نقابة مهن هندسية | B16: 0.0045 | C16: =B16*D9 -> 11423.826
A17: دمغة نقابة مهن تطبيقية | B17: 0 | C17: 0
A18: تامينات اجتماعية | B18: 0 | C18: =B18*D9 -> 0
A19: أرباح تجارية وصناعية | B19: 0 | C19: =B19*D9 -> 0
A20: ضريبة القيمة المضافة | B20: 0.05 | C20: =B20*D8 -> 126931.4
A21: الاتحاد المصري | B21: 0 | C21: 0
A22: تحيا مصر | B22: 0.01 | C22: =B22*D9 -> 25386.28
A23: تراخيص | B23: 0 | C23: 10000
A24: غرامة تأخير | B24: 0 | C24: 0
A25: عائد استثمار رصيد دفعة مقدمة | B25: 0 | C25: 0
A26: تعليات لحين سداد التامينات | B26: 0 | C26: 0
A27: تعلية بنود متجاوزة | B27: 0 | C27: 0
A28: تعلية بنود مستجدة | B28: 0 | C28: 0
A29: استهلاك الدفعة المقدمة | B29: 0.1 | C29: =0.1*D10 -> 266555.94
A30: محضر الاستلام | B30: 0 | C30: 0
A31: تامين نهائي | B31: 0.1 | C31: 0
A32: معلى للشركة في الدائنة | B32: 0 | C32: 0
A33: عائد كميات / نسب سالبة | B33: 0 | C33: 0
A34: معلى لحساب الشركة | B34: 0 | C34: 0
A35: جملة الاستقطاعات | C35: =SUM(C12:D34) -> 641356.79
A36: الصافي بعد الاستقطاعات | C36: =D6-C35 -> 2024202.6
B40: 0 | E40: =8061000-C36 -> 6036797.4
C41: الله اكبر -تحيا غزة العزة - تحيا مصر
A87: 7_5
A88: 7_6
...

Sheet بيان الاعمال
A1: وزارة الإسكان والمرافق والمجتمعات العمرانية هيئة المجتمعات العمرانية الجديدة جهاز تنمية مدينة العبور الجديدة | E1: بيان اعمال مستخلص رقم ( 33) جارى - عملية ( 3 ) | O1: مشروع / عملية رقم 3 لإنشاء عدد 54عمارة إسكان اجتماعي - مدينة العبور الجديدة الحى 15 شركة المقاولات المسند اليها المشروع /احمد سعد عبد الجواد بموجب امر إسناد رقم (66 )بتاريخ 2022/9/15 | V1: بيان اعمال مستخلص رقم ( 33) جارى - عملية ( 3 ) | AF1: مشروع / عملية رقم 3 لإنشاء عدد 54عمارة إسكان اجتماعي - مدينة العبور الجديدة الحى 15 شركة المقاولات المسند اليها المشروع /احمد سعد عبد الجواد بموجب امر إسناد رقم (66 )بتاريخ 2022/9/15 | AN1: بيان اعمال مستخلص رقم (33) جارى - عملية ( 3 ) | BA1: مشروع / عملية رقم 3 لإنشاء عدد 54عمارة إسكان اجتماعي - مدينة العبور الجديدة الحى 15 شركة المقاولات المسند اليها المشروع /احمد سعد عبد الجواد بموجب امر إسناد رقم (66 )بتاريخ 2022/9/15
A2: بند / ارقام العمارات | E2: 300 | F2: 301 | G2: 302 | H2: 303 | I2: 304 | J2: 305 | K2: 306 | L2: 307 | M2: 308 | N2: 309 | O2: 310 | P2: 311 | Q2: 312 | R2: 313 | S2: 314 | T2: 315 | U2: 316 | V2: 317 | W2: 318 | X2: 319 | Y2: 320 | Z2: 321 | AA2: 322 | AB2: 323 | AC2: 324 | AD2: 325 | AE2: 326 | AF2: 327 | AG2: 328 | AH2: 329 | AI2: 330 | AJ2: 331 | AK2: 332 | AL2: 333 | AM2: 334 | AN2: 335 | AO2: 336 | AP2: 337 | AQ2: 338 | AR2: 339 | AS2: 340 | AT2: 341 | AU2: 342 | AV2: 343 | AW2: 344 | AX2: 345 | AY2: 346 | AZ2: 347 | BA2: 348 | BB2: 349 | BC2: 350 | BD2: 351 | BE2: 352 | BF2: 353 | BG2: اجمالى الكمية المنفذة | BH2: اجمالى الكمية فى المستخلص
A3: بند(1 - 1) بالمتر المكعب حفر لزوم الاساسات | C3: الكميه بالمقايسه | E3: 965 | F3: 965 | G3: 965 | H3: 965 | I3: 965 | J3: 965 | K3: 965 | L3: 965 | M3: 965 | N3: 965 | O3: 965 | P3: 965 | Q3: 965 | R3: 965 | S3: 965 | T3: 965 | U3: 965 | V3: 965 | W3: 965 | X3: 965 | Y3: 965 | Z3: 965 | AA3: 965 | AB3: 965 | AC3: 965 | AD3: 965 | AE3: 965 | AF3: 965 | AG3: 965 | AH3: 965 | AI3: 965 | AJ3: 965 | AK3: 965 | AL3: 965 | AM3: 965 | AN3: 965 | AO3: 965 | AP3: 965 | AQ3: 965 | AR3: 965 | AS3: 965 | AT3: 965 | AU3: 965 | AV3: 965 | AW3: 965 | AX3: 965 | AY3: 965 | AZ3: 965 | BA3: 965 | BB3: 965 | BC3: 965 | BD3: 965 | BE3: 965 | BF3: 965 | BG3: =SUM(E3:BF3) -> 52110 | BH3: =BG4 -> 72595.27 | BI3: =BG3/BF3 -> 54
C4: الكميه المنفذه | E4: 1431.17 | F4: 1538.93 | G4: 1148.09 | H4: 1727.22 | I4: 1718.78 | J4: 1328.94 | K4: 910.95 | L4: 916.68 | M4: 1289.08 | N4: 1403.67 | O4: 1082.83 | P4: 1237.52 | Q4: 2228.69 | R4: 1432.32 | S4: 939.6 | T4: 397.62 | U4: 639.04 | V4: 563.3 | W4: 1180.23 | X4: 1420.86 | Y4: 2532.34 | Z4: 1277.62 | AA4: 713.72 | AB4: 493.26 | AC4: 441.38 | AD4: 1913.58 | AE4: 2194.31 | AF4: 2263.06 | AG4: 2412.03 | AH4: 2045.35 | AI4: 2646.93 | AJ4: 710.05 | AK4: 710.05 | AL4: 814.19 | AM4: 1380.75 | AN4: 1890.66 | AO4: 2114.1 | AP4: 1438.04 | AQ4: 870.84 | AR4: 761.99 | AS4: 421.29 | AT4: 1873.47 | AU4: 2192.64 | AV4: 1701.59 | AW4: 899.49 | AX4: 1581.28 | AY4: 1410.18 | AZ4: 1205.43 | BA4: 516.13 | BB4: 790.88 | BC4: 1352.1 | BD4: 1278.34 | BE4: 1362.13 | BF4: 1850.55 | BG4: =SUM(E4:BF4) -> 72595.27 | BI4: =BG4/BF4 -> 39.229024
A5: بند(1- 2) بالمتر المكعب ردم من ناتج الحفر | C5: الكميه بالمقايسه | E5: 250 | F5: 250 | G5: 250 | H5: 250 | I5: 250 | J5: 250 | K5: 250 | L5: 250 | M5: 250 | N5: 250 | O5: 250 | P5: 250 | Q5: 250 | R5: 250 | S5: 250 | T5: 250 | U5: 250 | V5: 250 | W5: 250 | X5: 250 | Y5: 250 | Z5: 250 | AA5: 250 | AB5: 250 | AC5: 250 | AD5: 250 | AE5: 250 | AF5: 250 | AG5: 250 | AH5: 250 | AI5: 250 | AJ5: 250 | AK5: 250 | AL5: 250 | AM5: 250 | AN5: 250 | AO5: 250 | AP5: 250 | AQ5: 250 | AR5: 250 | AS5: 250 | AT5: 250 | AU5: 250 | AV5: 250 | AW5: 250 | AX5: 250 | AY5: 250 | AZ5: 250 | BA5: 250 | BB5: 250 | BC5: 250 | BD5: 250 | BE5: 250 | BF5: 250 | BG5: =SUM(E5:BF5) -> 13500 | BH5: =BG6 -> 0 | BI5: =BG5/BF5 -> 54
C6: الكميه المنفذه | BG6: =SUM(E6:BF6) -> 0 | BI6: =BG6/BF6 -> #DIV/0!
A7: بند(1-2) بالمتر المكعب ردم من ناتج الحفر | C7: الكميه بالمقايسه | E7: 250 | F7: 250 | G7: 250 | H7: 250 | I7: 250 | J7: 250 | K7: 250 | L7: 250 | M7: 250 | N7: 250 | O7: 250 | P7: 250 | Q7: 250 | R7: 250 | S7: 250 | T7: 250 | U7: 250 | V7: 250 | W7: 250 | X7: 250 | Y7: 250 | Z7: 250 | AA7: 250 | AB7: 250 | AC7: 250 | AD7: 250 | AE7: 250 | AF7: 250 | AG7: 250 | AH7: 250 | AI7: 250 | AJ7: 250 | AK7: 250 | AL7: 250 | AM7: 250 | AN7: 250 | AO7: 250 | AP7: 250 | AQ7: 250 | AR7: 250 | AS7: 250 | AT7: 250 | AU7: 250 | AV7: 250 | AW7: 250 | AX7: 250 | AY7: 250 | AZ7: 250 | BA7: 250 | BB7: 250 | BC7: 250 | BD7: 250 | BE7: 250 | BF7: 250 | BG7: =SUM(E7:BF7) -> 13500 | BH7: =BG8 -> 16848 | BI7: =BG7/BF7 -> 54
C8: الكميه المنفذه | E8: 312 | F8: 312 | G8: 312 | H8: 312 | I8: 312 | J8: 312 | K8: 312 | L8: 312 | M8: 312 | N8: 312 | O8: 312 | P8: 312 | Q8: 312 | R8: 312 | S8: 312 | T8: 312 | U8: 312 | V8: 312 | W8: 312 | X8: 312 | Y8: 312 | Z8: 312 | AA8: 312 | AB8: 312 | AC8: 312 | AD8: 312 | AE8: 312 | AF8: 312 | AG8: 312 | AH8: 312 | AI8: 312 | AJ8: 312 | AK8: 312 | AL8: 312 | AM8: 312 | AN8: 312 | AO8: 312 | AP8: 312 | AQ8: 312 | AR8: 312 | AS8: 312 | AT8: 312 | AU8: 312 | AV8: 312 | AW8: 312 | AX8: 312 | AY8: 312 | AZ8: 312 | BA8: 312 | BB8: 312 | BC8: 312 | BD8: 312 | BE8: 312 | BF8: 312 | BG8: =SUM(E8:BF8) -> 16848 | BI8: =BG8/BF8 -> 54
A9: بند(1- 4) بالمتر المكعب تربة احلال للاساسات برمال من خارج الموقع | C9: الكميه بالمقايسه | E9: 281 | F9: 281 | G9: 281 | H9: 281 | I9: 281 | J9: 281 | K9: 281 | L9: 281 | M9: 281 | N9: 281 | O9: 281 | P9: 281 | Q9: 281 | R9: 281 | S9: 281 | T9: 281 | U9: 281 | V9: 281 | W9: 281 | X9: 281 | Y9: 281 | Z9: 281 | AA9: 281 | AB9: 281 | AC9: 281 | AD9: 281 | AE9: 281 | AF9: 281 | AG9: 281 | AH9: 281 | AI9: 281 | AJ9: 281 | AK9: 281 | AL9: 281 | AM9: 281 | AN9: 281 | AO9: 281 | AP9: 281 | AQ9: 281 | AR9: 281 | AS9: 281 | AT9: 281 | AU9: 281 | AV9: 281 | AW9: 281 | AX9: 281 | AY9: 281 | AZ9: 281 | BA9: 281 | BB9: 281 | BC9: 281 | BD9: 281 | BE9: 281 | BF9: 281 | BG9: =SUM(E9:BF9) -> 15174 | BH9: =BG10 -> 30938.22 | BI9: =BG9/BF9 -> 54
C10: الكميه المنفذه | E10: 572.93 | F10: 1432.325 | G10: 1145.86 | H10: 572.93 | I10: 572.93 | J10: 859.395 | K10: 572.93 | L10: 572.93 | M10: 572.93 | N10: 859.395 | O10: 572.93 | P10: 859.395 | Q10: 1432.325 | R10: 572.93 | S10: 572.93 | T10: 0 | U10: 0 | V10: 0 | W10: 572.93 | X10: 572.93 | Y10: 1145.86 | Z10: 572.93 | AA10: 0 | AB10: 0 | AC10: 0 | AD10: 572.93 | AE10: 572.93 | AF10: 1145.86 | AG10: 572.93 | AH10: 572.93 | AI10: 572.93 | AJ10: 0 | AK10: 0 | AL10: 0 | AM10: 572.93 | AN10: 859.395 | AO10: 572.93 | AP10: 859.395 | AQ10: 572.93 | AR10: 286.465 | AS10: 286.465 | AT10: 572.93 | AU10: 859.395 | AV10: 572.93 | AW10: 572.93 | AX10: 572.93 | AY10: 572.93 | AZ10: 572.93 | BA10: 572.93 | BB10: 572.93 | BC10: 1145.86 | BD10: 572.93 | BE10: 572.93 | BF10: 572.93 | BG10: =SUM(E10:BF10) -> 30938.22 | BI10: =BG10/BF10 -> 54
A11: بند(1- 5) بالمتر المكعب تربة احلال اسفل الاساسات برمال وسن بنسبة 1:1 | C11: الكميه بالمقايسه | E11: 117 | F11: 117 | G11: 117 | H11: 117 | I11: 117 | J11: 117 | K11: 117 | L11: 117 | M11: 117 | N11: 117 | O11: 117 | P11: 117 | Q11: 117 | R11: 117 | S11: 117 | T11: 117 | U11: 117 | V11: 117 | W11: 117 | X11: 117 | Y11: 117 | Z11: 117 | AA11: 117 | AB11: 117 | AC11: 117 | AD11: 117 | AE11: 117 | AF11: 117 | AG11: 117 | AH11: 117 | AI11: 117 | AJ11: 117 | AK11: 117 | AL11: 117 | AM11: 117 | AN11: 117 | AO11: 117 | AP11: 117 | AQ11: 117 | AR11: 117 | AS11: 117 | AT11: 117 | AU11: 117 | AV11: 117 | AW11: 117 | AX11: 117 | AY11: 117 | AZ11: 117 | BA11: 117 | BB11: 117 | BC11: 117 | BD11: 117 | BE11: 117 | BF11: 117 | BG11: =SUM(E11:BF11) -> 6318 | BH11: =BG12 -> 6875.16 | BI11: =BG11/BF11 -> 54
C12: الكميه المنفذه | E12: 0 | F12: 0 | G12: 0 | H12: 859.395 | I12: 859.395 | J12: 0 | K12: 0 | L12: 0 | M12: 0 | N12: 0 | O12: 0 | P12: 0 | Q12: 0 | R12: 0 | S12: 0 | T12: 0 | U12: 0 | V12: 0 | W12: 0 | X12: 0 | Y12: 0 | Z12: 0 | AA12: 0 | AB12: 0 | AC12: 0 | AD12: 0 | AE12: 572.93 | AF12: 0 | AG12: 0 | AH12: 0 | AI12: 859.395 | AJ12: 0 | AK12: 0 | AL12: 0 | AM12: 0 | AN12: 0 | AO12: 859.395 | AP12: 0 | AQ12: 0 | AR12: 0 | AS12: 0 | AT12: 859.395 | AU12: 0 | AV12: 0 | AW12: 0 | AX12: 0 | AY12: 0 | AZ12: 0 | BA12: 0 | BB12: 0 | BC12: 0 | BD12: 572.93 | BE12: 572.93 | BF12: 859.395 | BG12: =SUM(E12:BF12) -> 6875.16 | BI12: =BG12/BF12 -> 8
A13: بند (2-1) بالمتر المكعب خرسانه عاديه للاساسات | C13: الكميه بالمقايسه | E13: 188 | F13: 188 | G13: 188 | H13: 188 | I13: 188 | J13: 188 | K13: 188 | L13: 188 | M13: 188 | N13: 188 | O13: 188 | P13: 188 | Q13: 188 | R13: 188 | S13: 188 | T13: 188 | U13: 188 | V13: 188 | W13: 188 | X13: 188 | Y13: 188 | Z13: 188 | AA13: 188 | AB13: 188 | AC13: 188 | AD13: 188 | AE13: 188 | AF13: 188 | AG13: 188 | AH13: 188 | AI13: 188 | AJ13: 188 | AK13: 188 | AL13: 188 | AM13: 188 | AN13: 188 | AO13: 188 | AP13: 188 | AQ13: 188 | AR13: 188 | AS13: 188 | AT13: 188 | AU13: 188 | AV13: 188 | AW13: 188 | AX13: 188 | AY13: 188 | AZ13: 188 | BA13: 188 | BB13: 188 | BC13: 188 | BD13: 188 | BE13: 188 | BF13: 188 | BG13: =SUM(E13:BF13) -> 10152 | BH13: =BG14 -> 10218.04 | BI13: =BG13/BF13 -> 54
C14: الكميه المنفذه | E14: 189.348 | F14: 189.348 | G14: 189.348 | H14: 189.348 | I14: 189.348 | J14: 189.348 | K14: 189.348 | L14: 189.348 | M14: 189.348 | N14: 189.348 | O14: 189.348 | P14: 189.348 | Q14: 189.348 | R14: 189.348 | S14: 189.348 | T14: 189.348 | U14: 189.348 | V14: 189.348 | W14: 189.348 | X14: 189.348 | Y14: 189.348 | Z14: 189.348 | AA14: 187.824 | AB14: 186.14 | AC14: 187.824 | AD14: 189.348 | AE14: 189.348 | AF14: 189.348 | AG14: 189.348 | AH14: 189.348 | AI14: 189.348 | AJ14: 189.348 | AK14: 189.348 | AL14: 189.348 | AM14: 189.348 | AN14: 189.348 | AO14: 189.348 | AP14: 189.348 | AQ14: 189.348 | AR14: 189.348 | AS14: 189.348 | AT14: 189.348 | AU14: 189.348 | AV14: 189.348 | AW14: 189.348 | AX14: 189.348 | AY14: 189.348 | AZ14: 189.348 | BA14: 189.348 | BB14: 189.348 | BC14: 189.348 | BD14: 189.348 | BE14: 189.2 | BF14: 189 | BG14: =SUM(E14:BF14) -> 10218.04 | BI14: =BG14/BF14 -> 54.063704 | BK14: =AX14+AI14+AH14+AG14+AC14+AB14+AA14+X14+W14 -> 1697.876 | BL14: =3*188 -> 564 | BM14: =BK14-BL14 -> 1133.876
A15: بند (2-2) بالمتر المكعب خرسانه مسلحه للاساسات | C15: الكميه بالمقايسه | E15: 200 | F15: 200 | G15: 200 | H15: 200 | I15: 200 | J15: 200 | K15: 200 | L15: 200 | M15: 200 | N15: 200 | O15: 200 | P15: 200 | Q15: 200 | R15: 200 | S15: 200 | T15: 200 | U15: 200 | V15: 200 | W15: 200 | X15: 200 | Y15: 200 | Z15: 200 | AA15: 200 | AB15: 200 | AC15: 200 | AD15: 200 | AE15: 200 | AF15: 200 | AG15: 200 | AH15: 200 | AI15: 200 | AJ15: 200 | AK15: 200 | AL15: 200 | AM15: 200 | AN15: 200 | AO15: 200 | AP15: 200 | AQ15: 200 | AR15: 200 | AS15: 200 | AT15: 200 | AU15: 200 | AV15: 200 | AW15: 200 | AX15: 200 | AY15: 200 | AZ15: 200 | BA15: 200 | BB15: 200 | BC15: 200 | BD15: 200 | BE15: 200 | BF15: 200 | BG15: =SUM(E15:BF15) -> 10800 | BH15: =BG16 -> 9445.236 | BI15: =BG15/BF15 -> 54
C16: الكميه المنفذه | E16: 166.752 | F16: 166.752 | G16: 166.752 | H16: 225.397 | I16: 225.397 | J16: 166.752 | K16: 166.752 | L16: 166.752 | M16: 166.752 | N16: 166.752 | O16: 166.752 | P16: 166.752 | Q16: 166.752 | R16: 166.752 | S16: 166.752 | T16: 166.752 | U16: 166.752 | V16: 166.752 | W16: 166.752 | X16: 166.752 | Y16: 166.752 | Z16: 166.752 | AA16: 167.562 | AB16: 168.372 | AC16: 167.562 | AD16: 166.752 | AE16: 166.752 | AF16: 166.752 | AG16: 195.735 | AH16: 195.735 | AI16: 225.397 | AJ16: 166.752 | AK16: 166.752 | AL16: 166.752 | AM16: 166.752 | AN16: 166.752 | AO16: 225.397 | AP16: 166.752 | AQ16: 166.752 | AR16: 166.752 | AS16: 166.752 | AT16: 225.397 | AU16: 166.752 | AV16: 166.752 | AW16: 166.752 | AX16: 195.735 | AY16: 166.752 | AZ16: 166.752 | BA16: 166.752 | BB16: 166.752 | BC16: 166.752 | BD16: 195.735 | BE16: 195.735 | BF16: 166 | BG16: =SUM(E16:BF16) -> 9445.236 | BI16: =BG16/175 -> 53.972777 | BK16: =AX16+AI16+AH16+AG16+AF16+AE16+Y16+X16+W16 -> 1646.362
A17: بند ( 3-1 ) بالمتر المسطح عمل دكة خرسانة مسلحة | C17: الكميه بالمقايسه | E17: 330 | F17: 330 | G17: 330 | H17: 330 | I17: 330 | J17: 330 | K17: 330 | L17: 330 | M17: 330 | N17: 330 | O17: 330 | P17: 330 | Q17: 330 | R17: 330 | S17: 330 | T17: 330 | U17: 330 | V17: 330 | W17: 330 | X17: 330 | Y17: 330 | Z17: 330 | AA17: 330 | AB17: 330 | AC17: 330 | AD17: 330 | AE17: 330 | AF17: 330 | AG17: 330 | AH17: 330 | AI17: 330 | AJ17: 330 | AK17: 330 | AL17: 330 | AM17: 330 | AN17: 330 | AO17: 330 | AP17: 330 | AQ17: 330 | AR17: 330 | AS17: 330 | AT17: 330 | AU17: 330 | AV17: 330 | AW17: 330 | AX17: 330 | AY17: 330 | AZ17: 330 | BA17: 330 | BB17: 330 | BC17: 330 | BD17: 330 | BE17: 330 | BF17: 330 | BG17: =SUM(E17:BF17) -> 17820 | BH17: =BG18 -> 18770.319 | BI17: =BG17/BF17 -> 54
C18: الكميه المنفذه | E18: 347.5985 | F18: 347.5985 | G18: 347.5985 | H18: 347.5985 | I18: 347.5985 | J18: 347.5985 | K18: 347.5985 | L18: 347.5985 | M18: 347.5985 | N18: 347.5985 | O18: 347.5985 | P18: 347.5985 | Q18: 347.5985 | R18: 347.5985 | S18: 347.5985 | T18: 347.5985 | U18: 347.5985 | V18: 347.5985 | W18: 347.5985 | X18: 347.5985 | Y18: 347.5985 | Z18: 347.5985 | AA18: 347.5985 | AB18: 347.5985 | AC18: 347.5985 | AD18: 347.5985 | AE18: 347.5985 | AF18: 347.5985 | AG18: 347.5985 | AH18: 347.5985 | AI18: 347.5985 | AJ18: 347.5985 | AK18: 347.5985 | AL18: 347.5985 | AM18: 347.5985 | AN18: 347.5985 | AO18: 347.5985 | AP18: 347.5985 | AQ18: 347.5985 | AR18: 347.5985 | AS18: 347.5985 | AT18: 347.5985 | AU18: 347.5985 | AV18: 347.5985 | AW18: 347.5985 | AX18: 347.5985 | AY18: 347.5985 | AZ18: 347.5985 | BA18: 347.5985 | BB18: 347.5985 | BC18: 347.5985 | BD18: 347.5985 | BE18: 347.5985 | BF18: 347.5985 | BG18: =SUM(E18:BF18) -> 18770.319 | BI18: =BG18/BF18 -> 54
A19: بند ( 3-2 ) بالمتر المسطح عمل خرسانه خفيفه لتخليق ميول الاسطح | C19: الكميه بالمقايسه | E19: 330 | F19: 330 | G19: 330 | H19: 330 | I19: 330 | J19: 330 | K19: 330 | L19: 330 | M19: 330 | N19: 330 | O19: 330 | P19: 330 | Q19: 330 | R19: 330 | S19: 330 | T19: 330 | U19: 330 | V19: 330 | W19: 330 | X19: 330 | Y19: 330 | Z19: 330 | AA19: 330 | AB19: 330 | AC19: 330 | AD19: 330 | AE19: 330 | AF19: 330 | AG19: 330 | AH19: 330 | AI19: 330 | AJ19: 330 | AK19: 330 | AL19: 330 | AM19: 330 | AN19: 330 | AO19: 330 | AP19: 330 | AQ19: 330 | AR19: 330 | AS19: 330 | AT19: 330 | AU19: 330 | AV19: 330 | AW19: 330 | AX19: 330 | AY19: 330 | AZ19: 330 | BA19: 330 | BB19: 330 | BC19: 330 | BD19: 330 | BE19: 330 | BF19: 330 | BG19: =SUM(E19:BF19) -> 17820 | BH19: =BG20 -> 18145.08 | BI19: =BG19/BF19 -> 54
C20: الكميه المنفذه | E20: 336.02 | F20: 336.02 | G20: 336.02 | H20: 336.02 | I20: 336.02 | J20: 336.02 | K20: 336.02 | L20: 336.02 | M20: 336.02 | N20: 336.02 | O20: 336.02 | P20: 336.02 | Q20: 336.02 | R20: 336.02 | S20: 336.02 | T20: 336.02 | U20: 336.02 | V20: 336.02 | W20: 336.02 | X20: 336.02 | Y20: 336.02 | Z20: 336.02 | AA20: 336.02 | AB20: 336.02 | AC20: 336.02 | AD20: 336.02 | AE20: 336.02 | AF20: 336.02 | AG20: 336.02 | AH20: 336.02 | AI20: 336.02 | AJ20: 336.02 | AK20: 336.02 | AL20: 336.02 | AM20: 336.02 | AN20: 336.02 | AO20: 336.02 | AP20: 336.02 | AQ20: 336.02 | AR20: 336.02 | AS20: 336.02 | AT20: 336.02 | AU20: 336.02 | AV20: 336.02 | AW20: 336.02 | AX20: 336.02 | AY20: 336.02 | AZ20: 336.02 | BA20: 336.02 | BB20: 336.02 | BC20: 336.02 | BD20: 336.02 | BE20: 336.02 | BF20: 336.02 | BG20: =SUM(E20:BF20) -> 18145.08 | BI20: =BG20/BF20 -> 54
A21: بند ( 3 - 3 ) أعمال الهيكل ( أسقف وسلالم ) | C21: الكميه بالمقايسه | E21: 385 | F21: 385 | G21: 385 | H21: 385 | I21: 385 | J21: 385 | K21: 385 | L21: 385 | M21: 385 | N21: 385 | O21: 385 | P21: 385 | Q21: 385 | R21: 385 | S21: 385 | T21: 385 | U21: 385 | V21: 385 | W21: 385 | X21: 385 | Y21: 385 | Z21: 385 | AA21: 385 | AB21: 385 | AC21: 385 | AD21: 385 | AE21: 385 | AF21: 385 | AG21: 385 | AH21: 385 | AI21: 385 | AJ21: 385 | AK21: 385 | AL21: 385 | AM21: 385 | AN21: 385 | AO21: 385 | AP21: 385 | AQ21: 385 | AR21: 385 | AS21: 385 | AT21: 385 | AU21: 385 | AV21: 385 | AW21: 385 | AX21: 385 | AY21: 385 | AZ21: 385 | BA21: 385 | BB21: 385 | BC21: 385 | BD21: 385 | BE21: 385 | BF21: 385 | BG21: =SUM(E21:BF21) -> 20790 | BI21: =BG21/BF21 -> 54
B22: بوادي السلالم | C22: الكميه المنفذه | E22: 1.653 | F22: 1.1974 | G22: 1.61883 | H22: 1.1974 | I22: 1.1974 | J22: 1.4252 | K22: 1.1974 | L22: 1.1974 | M22: 1.18601 | N22: 1.1974 | O22: 1.3113 | P22: 1.1974 | Q22: 1.3113 | R22: 1.58466 | S22: 1.77829 | T22: 1.74412 | U22: 1.49354 | V22: 1.9947 | W22: 1.9947 | X22: 1.1974 | Y22: 1.4252 | Z22: 1.1974 | AA22: 1.7669 | AB22: 1.7669 | AC22: 1.7669 | AD22: 1.92636 | AE22: 1.1974 | AF22: 1.1974 | AG22: 1.36825 | AH22: 1.1974 | AI22: 1.1974 | AJ22: 1.22018 | AK22: 1.63022 | AL22: 1.1974 | AM22: 1.7669 | AN22: 1.82385 | AO22: 1.1974 | AP22: 1.56188 | AQ22: 1.1974 | AR22: 1.48215 | AS22: 1.90358 | AT22: 1.1974 | AU22: 1.73273 | AV22: 1.1974 | AW22: 1.1974 | AX22: 1.1974 | AY22: 1.1974 | AZ22: 1.7669 | BA22: 1.7669 | BB22: 1.5391 | BC22: 1.1974 | BD22: 1.1974 | BE22: 1.1974 | BF22: 1.1974 | BG22: =SUM(E22:BF22) -> 77.24555 | BH22: =SUM(BG22:BG29) -> 20893.607
B23: سقف الارضى | C23: الكميه المنفذه | E23: 63.636395 | F23: 63.636395 | G23: 63.636395 | H23: 63.636395 | I23: 63.636395 | J23: 63.636395 | K23: 63.636395 | L23: 63.636395 | M23: 63.636395 | N23: 63.636395 | O23: 63.636395 | P23: 63.636395 | Q23: 63.636395 | R23: 63.636395 | S23: 63.636395 | T23: 63.636395 | U23: 63.636395 | V23: 63.636395 | W23: 63.636395 | X23: 63.636395 | Y23: 63.636395 | Z23: 63.636395 | AA23: 63.636395 | AB23: 63.636395 | AC23: 63.636395 | AD23: 63.636395 | AE23: 63.636395 | AF23: 63.636395 | AG23: 63.636395 | AH23: 63.636395 | AI23: 63.636395 | AJ23: 63.636395 | AK23: 63.636395 | AL23: 63.636395 | AM23: 63.636395 | AN23: 63.636395 | AO23: 63.636395 | AP23: 63.636395 | AQ23: 63.636395 | AR23: 63.636395 | AS23: 63.636395 | AT23: 63.636395 | AU23: 63.636395 | AV23: 63.636395 | AW23: 63.636395 | AX23: 63.636395 | AY23: 63.636395 | AZ23: 63.636395 | BA23: 63.636395 | BB23: 63.636395 | BC23: 63.636395 | BD23: 63.636395 | BE23: 63.636395 | BF23: 63.636395 | BG23: =SUM(E23:BF23) -> 3436.3653 | BI23: =BG23/BF23 -> 54 | BM23: عناصر فى طلبية الحديد
B24: سقف الاول | C24: الكميه المنفذه | E24: 59.99 | F24: 59.99 | G24: 59.99 | H24: 59.99 | I24: 59.99 | J24: 59.99 | K24: 59.99 | L24: 59.99 | M24: 59.99 | N24: 59.99 | O24: 59.99 | P24: 59.99 | Q24: 59.99 | R24: 59.99 | S24: 59.99 | T24: 59.99 | U24: 59.99 | V24: 59.99 | W24: 59.99 | X24: 59.99 | Y24: 59.99 | Z24: 59.99 | AA24: 59.99 | AB24: 59.99 | AC24: 59.99 | AD24: 59.99 | AE24: 59.99 | AF24: 59.99 | AG24: 59.99 | AH24: 59.99 | AI24: 59.99 | AJ24: 59.99 | AK24: 59.99 | AL24: 59.99 | AM24: 59.99 | AN24: 59.99 | AO24: 59.99 | AP24: 59.99 | AQ24: 59.99 | AR24: 59.99 | AS24: 59.99 | AT24: 59.99 | AU24: 59.99 | AV24: 59.99 | AW24: 59.99 | AX24: 59.99 | AY24: 59.99 | AZ24: 59.99 | BA24: 59.99 | BB24: 59.99 | BC24: 59.99 | BD24: 59.99 | BE24: 59.99 | BF24: 59.99 | BG24: =SUM(E24:BF24) -> 3239.46 | BI24: =BG24/BF24 -> 54 | BM24: عناصر كانت موجودة فى طلبية ال 1000 طن
B25: سقف الثانى | C25: الكميه المنفذه | E25: 60.065 | F25: 60.065 | G25: 60.065 | H25: 60.065 | I25: 60.065 | J25: 60.065 | K25: 60.065 | L25: 60.065 | M25: 60.065 | N25: 60.065 | O25: 60.065 | P25: 60.065 | Q25: 60.065 | R25: 60.065 | S25: 60.065 | T25: 60.065 | U25: 60.065 | V25: 60.065 | W25: 60.065 | X25: 60.065 | Y25: 60.065 | Z25: 60.065 | AA25: 60.065 | AB25: 60.065 | AC25: 60.065 | AD25: 60.065 | AE25: 60.065 | AF25: 60.065 | AG25: 60.065 | AH25: 60.065 | AI25: 60.065 | AJ25: 60.065 | AK25: 60.065 | AL25: 60.065 | AM25: 60.065 | AN25: 60.065 | AO25: 60.065 | AP25: 60.065 | AQ25: 60.065 | AR25: 60.065 | AS25: 60.065 | AT25: 60.065 | AU25: 60.065 | AV25: 60.065 | AW25: 60.065 | AX25: 60.065 | AY25: 60.065 | AZ25: 60.065 | BA25: 60.065 | BB25: 60.065 | BC25: 60.065 | BD25: 60.065 | BE25: 60.065 | BF25: 60.065 | BG25: =SUM(E25:BF25) -> 3243.51 | BI25: =BG25/BF25 -> 54 | BM25: عناصر جديدة تم توفيرها من التنفيذ
B26: سقف الثالث | C26: الكميه المنفذه | E26: 59.825725 | F26: 59.825725 | G26: 59.825725 | H26: 59.825725 | I26: 59.825725 | J26: 59.825725 | K26: 59.825725 | L26: 59.825725 | M26: 59.825725 | N26: 59.825725 | O26: 59.825725 | P26: 59.825725 | Q26: 59.825725 | R26: 59.825725 | S26: 59.825725 | T26: 59.825725 | U26: 59.825725 | V26: 59.825725 | W26: 59.825725 | X26: 59.825725 | Y26: 59.825725 | Z26: 59.825725 | AA26: 59.825725 | AB26: 59.825725 | AC26: 59.825725 | AD26: 59.825725 | AE26: 59.825725 | AF26: 59.825725 | AG26: 59.825725 | AH26: 59.825725 | AI26: 59.825725 | AJ26: 59.825725 | AK26: 59.825725 | AL26: 59.825725 | AM26: 59.825725 | AN26: 59.825725 | AO26: 59.825725 | AP26: 59.825725 | AQ26: 59.825725 | AR26: 59.825725 | AS26: 59.825725 | AT26: 59.825725 | AU26: 59.825725 | AV26: 59.825725 | AW26: 59.825725 | AX26: 59.825725 | AY26: 59.825725 | AZ26: 59.825725 | BA26: 59.825725 | BB26: 59.825725 | BC26: 59.825725 | BD26: 59.825725 | BE26: 59.825725 | BF26: 59.825725 | BG26: =SUM(E26:BF26) -> 3230.5892 | BI26: =BG26/BF26 -> 54
B27: سقف الرابع | C27: الكميه المنفذه | E27: 61.187773 | F27: 61.187773 | G27: 61.187773 | H27: 61.187773 | I27: 61.187773 | J27: 61.187773 | K27: 61.187773 | L27: 61.187773 | M27: 61.187773 | N27: 61.187773 | O27: 61.187773 | P27: 61.187773 | Q27: 61.187773 | R27: 61.187773 | S27: 61.187773 | T27: 61.187773 | U27: 61.187773 | V27: 61.187773 | W27: 61.187773 | X27: 61.187773 | Y27: 61.187773 | Z27: 61.187773 | AA27: 61.187773 | AB27: 61.187773 | AC27: 61.187773 | AD27: 61.187773 | AE27: 61.187773 | AF27: 61.187773 | AG27: 61.187773 | AH27: 61.187773 | AI27: 61.187773 | AJ27: 61.187773 | AK27: 61.187773 | AL27: 61.187773 | AM27: 61.187773 | AN27: 61.187773 | AO27: 61.187773 | AP27: 61.187773 | AQ27: 61.187773 | AR27: 61.187773 | AS27: 61.187773 | AT27: 61.187773 | AU27: 61.187773 | AV27: 61.187773 | AW27: 61.187773 | AX27: 61.187773 | AY27: 61.187773 | AZ27: 61.187773 | BA27: 61.187773 | BB27: 61.187773 | BC27: 61.187773 | BD27: 61.187773 | BE27: 61.187773 | BF27: 61.187773 | BG27: =SUM(E27:BF27) -> 3304.1397 | BI27: =BG27/BF27 -> 54
B28: سقف الخامس | C28: الكميه المنفذه | E28: 70.951319 | F28: 70.951319 | G28: 70.951319 | H28: 70.951319 | I28: 70.951319 | J28: 70.951319 | K28: 70.951319 | L28: 70.951319 | M28: 70.951319 | N28: 70.951319 | O28: 70.951319 | P28: 70.951319 | Q28: 70.951319 | R28: 70.951319 | S28: 70.951319 | T28: 70.951319 | U28: 70.951319 | V28: 70.951319 | W28: 70.951319 | X28: 70.951319 | Y28: 70.951319 | Z28: 70.951319 | AA28: 70.951319 | AB28: 70.951319 | AC28: 70.951319 | AD28: 70.951319 | AE28: 70.951319 | AF28: 70.951319 | AG28: 70.951319 | AH28: 70.951319 | AI28: 70.951319 | AJ28: 70.951319 | AK28: 70.951319 | AL28: 70.951319 | AM28: 70.951319 | AN28: 70.951319 | AO28: 70.951319 | AP28: 70.951319 | AQ28: 70.951319 | AR28: 70.951319 | AS28: 70.951319 | AT28: 70.951319 | AU28: 70.951319 | AV28: 70.951319 | AW28: 70.951319 | AX28: 70.951319 | AY28: 70.951319 | AZ28: 70.951319 | BA28: 70.951319 | BB28: 70.951319 | BC28: 70.951319 | BD28: 70.951319 | BE28: 70.951319 | BF28: 70.951319 | BG28: =SUM(E28:BF28) -> 3831.3712 | BI28: =BG28/BF28 -> 54
B29: طبان دروة السطح | C29: الكميه المنفذه | E29: 9.83196 | F29: 9.83196 | G29: 9.83196 | H29: 9.83196 | I29: 9.83196 | J29: 9.83196 | K29: 9.83196 | L29: 9.83196 | M29: 9.83196 | N29: 9.83196 | O29: 9.83196 | P29: 9.83196 | Q29: 9.83196 | R29: 9.83196 | S29: 9.83196 | T29: 9.83196 | U29: 9.83196 | V29: 9.83196 | W29: 9.83196 | X29: 9.83196 | Y29: 9.83196 | Z29: 9.83196 | AA29: 9.83196 | AB29: 9.83196 | AC29: 9.83196 | AD29: 9.83196 | AE29: 9.83196 | AF29: 9.83196 | AG29: 9.83196 | AH29: 9.83196 | AI29: 9.83196 | AJ29: 9.83196 | AK29: 9.83196 | AL29: 9.83196 | AM29: 9.83196 | AN29: 9.83196 | AO29: 9.83196 | AP29: 9.83196 | AQ29: 9.83196 | AR29: 9.83196 | AS29: 9.83196 | AT29: 9.83196 | AU29: 9.83196 | AV29: 9.83196 | AW29: 9.83196 | AX29: 9.83196 | AY29: 9.83196 | AZ29: 9.83196 | BA29: 9.83196 | BB29: 9.83196 | BC29: 9.83196 | BD29: 9.83196 | BE29: 9.83196 | BF29: 9.83196 | BG29: =SUM(E29:BF29) -> 530.92584 | BI29: =BG29/BF29 -> 54
A30: بند ( 3 - 3 ) أعمال الهيكل ( أعمدة ) | C30: الكميه بالمقايسه | E30: 121 | F30: 121 | G30: 121 | H30: 121 | I30: 121 | J30: 121 | K30: 121 | L30: 121 | M30: 121 | N30: 121 | O30: 121 | P30: 121 | Q30: 121 | R30: 121 | S30: 121 | T30: 121 | U30: 121 | V30: 121 | W30: 121 | X30: 121 | Y30: 121 | Z30: 121 | AA30: 121 | AB30: 121 | AC30: 121 | AD30: 121 | AE30: 121 | AF30: 121 | AG30: 121 | AH30: 121 | AI30: 121 | AJ30: 121 | AK30: 121 | AL30: 121 | AM30: 121 | AN30: 121 | AO30: 121 | AP30: 121 | AQ30: 121 | AR30: 121 | AS30: 121 | AT30: 121 | AU30: 121 | AV30: 121 | AW30: 121 | AX30: 121 | AY30: 121 | AZ30: 121 | BA30: 121 | BB30: 121 | BC30: 121 | BD30: 121 | BE30: 121 | BF30: 121 | BG30: =SUM(E30:BF30) -> 6534 | BI30: =BG30/BF30 -> 54
B31: أعمدة أرضي | C31: الكميه المنفذه | E31: 37.11 | F31: 34.03 | G31: 36.88 | H31: 34.03 | I31: 34.03 | J31: 35.57 | K31: 34.03 | L31: 34.03 | M31: 33.96 | N31: 34.03 | O31: 34.8 | P31: 34.03 | Q31: 34.8 | R31: 36.64 | S31: 37.95 | T31: 37.72 | U31: 36.03 | V31: 39.41 | W31: 39.41 | X31: 34.03878 | Y31: 35.57478 | Z31: 34.03878 | AA31: 37.87878 | AB31: 37.87878 | AC31: 37.87878 | AD31: 38.95398 | AE31: 34.03878 | AF31: 34.03878 | AG31: 35.19078 | AH31: 34.03878 | AI31: 34.03878 | AJ31: 34.19238 | AK31: 36.95718 | AL31: 34.03878 | AM31: 37.87878 | AN31: 38.26278 | AO31: 34.03878 | AP31: 36.49638 | AQ31: 34.03878 | AR31: 35.95878 | AS31: 38.80038 | AT31: 34.03878 | AU31: 37.64838 | AV31: 34.03878 | AW31: 34.03878 | AX31: 34.03878 | AY31: 34.03878 | AZ31: 37.87878 | BA31: 37.87878 | BB31: 36.34278 | BC31: 34.03878 | BD31: 34.03878 | BE31: 34.03878 | BF31: 34.03878 | BG31: =SUM(E31:BF31) -> 1922.8393 | BH31: =SUM(BG31:BG37) -> 6476.3472 | BI31: =BG31/37 -> 51.96863
B32: اعمده الاول | C32: الكميه المنفذه | E32: 18.03082 | F32: 18.03082 | G32: 18.03082 | H32: 18.03082 | I32: 18.03082 | J32: 18.03082 | K32: 18.03082 | L32: 18.03082 | M32: 18.03082 | N32: 18.03082 | O32: 18.03082 | P32: 18.03082 | Q32: 18.03082 | R32: 18.03082 | S32: 18.03082 | T32: 18.03082 | U32: 18.03082 | V32: 18.03082 | W32: 18.03082 | X32: 18.03082 | Y32: 18.03082 | Z32: 18.03082 | AA32: 18.03082 | AB32: 18.03082 | AC32: 18.03082 | AD32: 18.03082 | AE32: 18.03082 | AF32: 18.03082 | AG32: 18.03082 | AH32: 18.03082 | AI32: 18.03082 | AJ32: 18.03082 | AK32: 18.03082 | AL32: 18.03082 | AM32: 18.03082 | AN32: 18.03082 | AO32: 18.03082 | AP32: 18.03082 | AQ32: 18.03082 | AR32: 18.03082 | AS32: 18.03082 | AT32: 18.03082 | AU32: 18.03082 | AV32: 18.03082 | AW32: 18.03082 | AX32: 18.03082 | AY32: 18.03082 | AZ32: 18.03082 | BA32: 18.03082 | BB32: 18.03082 | BC32: 18.03082 | BD32: 18.03082 | BE32: 18.03082 | BF32: 18.03082 | BG32: =SUM(E32:BF32) -> 973.66428 | BI32: =BG32/BF32 -> 54
B33: اعمده ثانى | C33: الكميه المنفذه | E33: 17.5954 | F33: 17.5954 | G33: 17.5954 | H33: 17.5954 | I33: 17.5954 | J33: 17.5954 | K33: 17.5954 | L33: 17.5954 | M33: 17.5954 | N33: 17.5954 | O33: 17.5954 | P33: 17.5954 | Q33: 17.5954 | R33: 17.5954 | S33: 17.5954 | T33: 17.5954 | U33: 17.5954 | V33: 17.5954 | W33: 17.5954 | X33: 17.5954 | Y33: 17.5954 | Z33: 17.5954 | AA33: 17.5954 | AB33: 17.5954 | AC33: 17.5954 | AD33: 17.5954 | AE33: 17.5954 | AF33: 17.5954 | AG33: 17.5954 | AH33: 17.5954 | AI33: 17.5954 | AJ33: 17.5954 | AK33: 17.5954 | AL33: 17.5954 | AM33: 17.5954 | AN33: 17.5954 | AO33: 17.5954 | AP33: 17.5954 | AQ33: 17.5954 | AR33: 17.5954 | AS33: 17.5954 | AT33: 17.5954 | AU33: 17.5954 | AV33: 17.5954 | AW33: 17.5954 | AX33: 17.5954 | AY33: 17.5954 | AZ33: 17.5954 | BA33: 17.5954 | BB33: 17.5954 | BC33: 17.5954 | BD33: 17.5954 | BE33: 17.5954 | BF33: 17.5954 | BG33: =SUM(E33:BF33) -> 950.1516 | BI33: =BG33/BF33 -> 54 | BJ33: 1618
B34: اعمده ثالت | C34: الكميه المنفذه | E34: 15.5684 | F34: 15.5684 | G34: 15.5684 | H34: 15.5684 | I34: 15.5684 | J34: 15.5684 | K34: 15.5684 | L34: 15.5684 | M34: 15.5684 | N34: 15.5684 | O34: 15.5684 | P34: 15.5684 | Q34: 15.5684 | R34: 15.5684 | S34: 15.5684 | T34: 15.5684 | U34: 15.5684 | V34: 15.5684 | W34: 15.5684 | X34: 15.5684 | Y34: 15.5684 | Z34: 15.5684 | AA34: 15.5684 | AB34: 15.5684 | AC34: 15.5684 | AD34: 15.5684 | AE34: 15.5684 | AF34: 15.5684 | AG34: 15.5684 | AH34: 15.5684 | AI34: 15.5684 | AJ34: 15.5684 | AK34: 15.5684 | AL34: 15.5684 | AM34: 15.5684 | AN34: 15.5684 | AO34: 15.5684 | AP34: 15.5684 | AQ34: 15.5684 | AR34: 15.5684 | AS34: 15.5684 | AT34: 15.5684 | AU34: 15.5684 | AV34: 15.5684 | AW34: 15.5684 | AX34: 15.5684 | AY34: 15.5684 | AZ34: 15.5684 | BA34: 15.5684 | BB34: 15.5684 | BC34: 15.5684 | BD34: 15.5684 | BE34: 15.5684 | BF34: 15.5684 | BG34: =SUM(E34:BF34) -> 840.6936 | BI34: =BG34/BF34 -> 54 | BJ34: 1919.05
B35: اعمده رابع | C35: الكميه المنفذه | E35: 15.5684 | F35: 15.5684 | G35: 15.5684 | H35: 15.5684 | I35: 15.5684 | J35: 15.5684 | K35: 15.5684 | L35: 15.5684 | M35: 15.5684 | N35: 15.5684 | O35: 15.5684 | P35: 15.5684 | Q35: 15.5684 | R35: 15.5684 | S35: 15.5684 | T35: 15.5684 | U35: 15.5684 | V35: 15.5684 | W35: 15.5684 | X35: 15.5684 | Y35: 15.5684 | Z35: 15.5684 | AA35: 15.5684 | AB35: 15.5684 | AC35: 15.5684 | AD35: 15.5684 | AE35: 15.5684 | AF35: 15.5684 | AG35: 15.5684 | AH35: 15.5684 | AI35: 15.5684 | AJ35: 15.5684 | AK35: 15.5684 | AL35: 15.5684 | AM35: 15.5684 | AN35: 15.5684 | AO35: 15.5684 | AP35: 15.5684 | AQ35: 15.5684 | AR35: 15.5684 | AS35: 15.5684 | AT35: 15.5684 | AU35: 15.5684 | AV35: 15.5684 | AW35: 15.5684 | AX35: 15.5684 | AY35: 15.5684 | AZ35: 15.5684 | BA35: 15.5684 | BB35: 15.5684 | BC35: 15.5684 | BD35: 15.5684 | BE35: 15.5684 | BF35: 15.5684 | BG35: =SUM(E35:BF35) -> 840.6936 | BI35: =BG35/BF35 -> 54 | BJ35: =BJ34-BJ33 -> 301.05 | BK35: =BE32+BB35+BA34+AZ32+AW31+AR33+AN31+AC33+AA33+S32+K31+G32+F33+E33 -> 297.56864
